[2022-01-25 10:38:09,569] {taskinstance.py:851} INFO - Dependencies all met for <TaskInstance: classification.apply_model 2022-01-25T10:36:56.507517+00:00 [queued]>
[2022-01-25 10:38:09,596] {taskinstance.py:851} INFO - Dependencies all met for <TaskInstance: classification.apply_model 2022-01-25T10:36:56.507517+00:00 [queued]>
[2022-01-25 10:38:09,596] {taskinstance.py:1042} INFO - 
--------------------------------------------------------------------------------
[2022-01-25 10:38:09,597] {taskinstance.py:1043} INFO - Starting attempt 1 of 2
[2022-01-25 10:38:09,597] {taskinstance.py:1044} INFO - 
--------------------------------------------------------------------------------
[2022-01-25 10:38:09,611] {taskinstance.py:1063} INFO - Executing <Task(PythonOperator): apply_model> on 2022-01-25T10:36:56.507517+00:00
[2022-01-25 10:38:09,618] {standard_task_runner.py:52} INFO - Started process 144 to run task
[2022-01-25 10:38:09,627] {standard_task_runner.py:76} INFO - Running: ['airflow', 'tasks', 'run', 'classification', 'apply_model', '2022-01-25T10:36:56.507517+00:00', '--job-id', '88', '--pool', 'default_pool', '--raw', '--subdir', 'DAGS_FOLDER/classification.py', '--cfg-path', '/tmp/tmp9_r3b83f', '--error-file', '/tmp/tmpgllgat6q']
[2022-01-25 10:38:09,634] {standard_task_runner.py:77} INFO - Job 88: Subtask apply_model
[2022-01-25 10:38:09,696] {logging_mixin.py:104} INFO - Running <TaskInstance: classification.apply_model 2022-01-25T10:36:56.507517+00:00 [running]> on host 327d6291ad28
[2022-01-25 10:38:09,775] {taskinstance.py:1257} INFO - Exporting the following env vars:
AIRFLOW_CTX_DAG_OWNER=airflow
AIRFLOW_CTX_DAG_ID=classification
AIRFLOW_CTX_TASK_ID=apply_model
AIRFLOW_CTX_EXECUTION_DATE=2022-01-25T10:36:56.507517+00:00
AIRFLOW_CTX_DAG_RUN_ID=manual__2022-01-25T10:36:56.507517+00:00
[2022-01-25 10:38:15,286] {taskinstance.py:1455} ERROR - [Errno 2] No such file or directory: '/opt/airflow/dags/process_dir/bulbasaur_bulbasaur_bulbasaur_bulbasaur_bulbasaur_bulbasaur_bulbasaur_bulbasaur_bulbasaur_bulbasaur_pikachu_654.jpeg'
Traceback (most recent call last):
  File "/home/airflow/.local/lib/python3.6/site-packages/airflow/models/taskinstance.py", line 1112, in _run_raw_task
    self._prepare_and_execute_task_with_callbacks(context, task)
  File "/home/airflow/.local/lib/python3.6/site-packages/airflow/models/taskinstance.py", line 1285, in _prepare_and_execute_task_with_callbacks
    result = self._execute_task(context, task_copy)
  File "/home/airflow/.local/lib/python3.6/site-packages/airflow/models/taskinstance.py", line 1315, in _execute_task
    result = task_copy.execute(context=context)
  File "/home/airflow/.local/lib/python3.6/site-packages/airflow/operators/python.py", line 117, in execute
    return_value = self.execute_callable()
  File "/home/airflow/.local/lib/python3.6/site-packages/airflow/operators/python.py", line 128, in execute_callable
    return self.python_callable(*self.op_args, **self.op_kwargs)
  File "/opt/airflow/dags/classification.py", line 104, in apply_dl_model
    img = image.load_img(os.path.join(process_dir,filename), target_size=(64, 64))
  File "/usr/local/lib/python3.6/site-packages/keras/preprocessing/image.py", line 314, in load_img
    target_size=target_size, interpolation=interpolation)
  File "/usr/local/lib/python3.6/site-packages/keras_preprocessing/image/utils.py", line 113, in load_img
    with open(path, 'rb') as f:
FileNotFoundError: [Errno 2] No such file or directory: '/opt/airflow/dags/process_dir/bulbasaur_bulbasaur_bulbasaur_bulbasaur_bulbasaur_bulbasaur_bulbasaur_bulbasaur_bulbasaur_bulbasaur_pikachu_654.jpeg'
[2022-01-25 10:38:15,294] {taskinstance.py:1503} INFO - Marking task as UP_FOR_RETRY. dag_id=classification, task_id=apply_model, execution_date=20220125T103656, start_date=20220125T103809, end_date=20220125T103815
[2022-01-25 10:38:15,359] {local_task_job.py:146} INFO - Task exited with return code 1
