[2022-01-25 14:50:25,080] {taskinstance.py:851} INFO - Dependencies all met for <TaskInstance: classification.save_result 2022-01-25T14:49:53.660687+00:00 [queued]>
[2022-01-25 14:50:25,092] {taskinstance.py:851} INFO - Dependencies all met for <TaskInstance: classification.save_result 2022-01-25T14:49:53.660687+00:00 [queued]>
[2022-01-25 14:50:25,093] {taskinstance.py:1042} INFO - 
--------------------------------------------------------------------------------
[2022-01-25 14:50:25,093] {taskinstance.py:1043} INFO - Starting attempt 1 of 2
[2022-01-25 14:50:25,094] {taskinstance.py:1044} INFO - 
--------------------------------------------------------------------------------
[2022-01-25 14:50:25,111] {taskinstance.py:1063} INFO - Executing <Task(PythonOperator): save_result> on 2022-01-25T14:49:53.660687+00:00
[2022-01-25 14:50:25,118] {standard_task_runner.py:52} INFO - Started process 2733 to run task
[2022-01-25 14:50:25,123] {standard_task_runner.py:76} INFO - Running: ['airflow', 'tasks', 'run', 'classification', 'save_result', '2022-01-25T14:49:53.660687+00:00', '--job-id', '180', '--pool', 'default_pool', '--raw', '--subdir', 'DAGS_FOLDER/classification.py', '--cfg-path', '/tmp/tmpekrxz2nh', '--error-file', '/tmp/tmpqe_dn1jh']
[2022-01-25 14:50:25,128] {standard_task_runner.py:77} INFO - Job 180: Subtask save_result
[2022-01-25 14:50:25,179] {logging_mixin.py:104} INFO - Running <TaskInstance: classification.save_result 2022-01-25T14:49:53.660687+00:00 [running]> on host 42ecca77b6ba
[2022-01-25 14:50:25,226] {taskinstance.py:1257} INFO - Exporting the following env vars:
AIRFLOW_CTX_DAG_OWNER=airflow
AIRFLOW_CTX_DAG_ID=classification
AIRFLOW_CTX_TASK_ID=save_result
AIRFLOW_CTX_EXECUTION_DATE=2022-01-25T14:49:53.660687+00:00
AIRFLOW_CTX_DAG_RUN_ID=manual__2022-01-25T14:49:53.660687+00:00
[2022-01-25 14:50:25,328] {logging_mixin.py:104} INFO - hello
[2022-01-25 14:50:25,560] {taskinstance.py:1455} ERROR - Failed to upload /opt/airflow/dags/process_dir/bulbasaur_charmander_12.jpeg to pokemon.sourcebucket/bulbasaur/charmander_12.jpeg: An error occurred (AccessDenied) when calling the PutObject operation: Access Denied
Traceback (most recent call last):
  File "/home/airflow/.local/lib/python3.6/site-packages/boto3/s3/transfer.py", line 279, in upload_file
    future.result()
  File "/home/airflow/.local/lib/python3.6/site-packages/s3transfer/futures.py", line 106, in result
    return self._coordinator.result()
  File "/home/airflow/.local/lib/python3.6/site-packages/s3transfer/futures.py", line 265, in result
    raise self._exception
  File "/home/airflow/.local/lib/python3.6/site-packages/s3transfer/tasks.py", line 126, in __call__
    return self._execute_main(kwargs)
  File "/home/airflow/.local/lib/python3.6/site-packages/s3transfer/tasks.py", line 150, in _execute_main
    return_value = self._main(**kwargs)
  File "/home/airflow/.local/lib/python3.6/site-packages/s3transfer/upload.py", line 692, in _main
    client.put_object(Bucket=bucket, Key=key, Body=body, **extra_args)
  File "/home/airflow/.local/lib/python3.6/site-packages/botocore/client.py", line 357, in _api_call
    return self._make_api_call(operation_name, kwargs)
  File "/home/airflow/.local/lib/python3.6/site-packages/botocore/client.py", line 676, in _make_api_call
    raise error_class(parsed_response, operation_name)
botocore.exceptions.ClientError: An error occurred (AccessDenied) when calling the PutObject operation: Access Denied

During handling of the above exception, another exception occurred:

Traceback (most recent call last):
  File "/home/airflow/.local/lib/python3.6/site-packages/airflow/models/taskinstance.py", line 1112, in _run_raw_task
    self._prepare_and_execute_task_with_callbacks(context, task)
  File "/home/airflow/.local/lib/python3.6/site-packages/airflow/models/taskinstance.py", line 1285, in _prepare_and_execute_task_with_callbacks
    result = self._execute_task(context, task_copy)
  File "/home/airflow/.local/lib/python3.6/site-packages/airflow/models/taskinstance.py", line 1315, in _execute_task
    result = task_copy.execute(context=context)
  File "/home/airflow/.local/lib/python3.6/site-packages/airflow/operators/python.py", line 117, in execute
    return_value = self.execute_callable()
  File "/home/airflow/.local/lib/python3.6/site-packages/airflow/operators/python.py", line 128, in execute_callable
    return self.python_callable(*self.op_args, **self.op_kwargs)
  File "/opt/airflow/dags/classification.py", line 138, in save_result
    result = clients3.upload_file(os.path.join(process_dir,filename), "pokemon.sourcebucket", predict_label+"/"+img)
  File "/home/airflow/.local/lib/python3.6/site-packages/boto3/s3/inject.py", line 131, in upload_file
    extra_args=ExtraArgs, callback=Callback)
  File "/home/airflow/.local/lib/python3.6/site-packages/boto3/s3/transfer.py", line 287, in upload_file
    filename, '/'.join([bucket, key]), e))
boto3.exceptions.S3UploadFailedError: Failed to upload /opt/airflow/dags/process_dir/bulbasaur_charmander_12.jpeg to pokemon.sourcebucket/bulbasaur/charmander_12.jpeg: An error occurred (AccessDenied) when calling the PutObject operation: Access Denied
[2022-01-25 14:50:25,572] {taskinstance.py:1503} INFO - Marking task as UP_FOR_RETRY. dag_id=classification, task_id=save_result, execution_date=20220125T144953, start_date=20220125T145025, end_date=20220125T145025
[2022-01-25 14:50:25,615] {local_task_job.py:146} INFO - Task exited with return code 1
