[2022-01-25 11:02:55,995] {taskinstance.py:851} INFO - Dependencies all met for <TaskInstance: classification.apply_model 2022-01-25T10:52:24.583418+00:00 [queued]>
[2022-01-25 11:02:56,021] {taskinstance.py:851} INFO - Dependencies all met for <TaskInstance: classification.apply_model 2022-01-25T10:52:24.583418+00:00 [queued]>
[2022-01-25 11:02:56,022] {taskinstance.py:1042} INFO - 
--------------------------------------------------------------------------------
[2022-01-25 11:02:56,024] {taskinstance.py:1043} INFO - Starting attempt 2 of 2
[2022-01-25 11:02:56,026] {taskinstance.py:1044} INFO - 
--------------------------------------------------------------------------------
[2022-01-25 11:02:56,062] {taskinstance.py:1063} INFO - Executing <Task(PythonOperator): apply_model> on 2022-01-25T10:52:24.583418+00:00
[2022-01-25 11:02:56,075] {standard_task_runner.py:52} INFO - Started process 9064 to run task
[2022-01-25 11:02:56,085] {standard_task_runner.py:76} INFO - Running: ['airflow', 'tasks', 'run', 'classification', 'apply_model', '2022-01-25T10:52:24.583418+00:00', '--job-id', '107', '--pool', 'default_pool', '--raw', '--subdir', 'DAGS_FOLDER/classification.py', '--cfg-path', '/tmp/tmpx67wwtho', '--error-file', '/tmp/tmpwyibprb7']
[2022-01-25 11:02:56,093] {standard_task_runner.py:77} INFO - Job 107: Subtask apply_model
[2022-01-25 11:02:56,231] {logging_mixin.py:104} INFO - Running <TaskInstance: classification.apply_model 2022-01-25T10:52:24.583418+00:00 [running]> on host 54a54d544bf0
[2022-01-25 11:02:56,343] {taskinstance.py:1257} INFO - Exporting the following env vars:
AIRFLOW_CTX_DAG_OWNER=airflow
AIRFLOW_CTX_DAG_ID=classification
AIRFLOW_CTX_TASK_ID=apply_model
AIRFLOW_CTX_EXECUTION_DATE=2022-01-25T10:52:24.583418+00:00
AIRFLOW_CTX_DAG_RUN_ID=scheduled__2022-01-25T10:52:24.583418+00:00
[2022-01-25 11:05:02,267] {logging_mixin.py:104} WARNING - /usr/local/lib/python3.6/site-packages/PIL/Image.py:976 UserWarning: Palette images with Transparency expressed in bytes should be converted to RGBA images
[2022-01-25 11:05:58,119] {taskinstance.py:1455} ERROR - [Errno 2] No such file or directory: '/opt/airflow/dags/process_dir/bulbasaur_bulbasaur_pikachu_654.jpeg'
Traceback (most recent call last):
  File "/home/airflow/.local/lib/python3.6/site-packages/airflow/models/taskinstance.py", line 1112, in _run_raw_task
    self._prepare_and_execute_task_with_callbacks(context, task)
  File "/home/airflow/.local/lib/python3.6/site-packages/airflow/models/taskinstance.py", line 1285, in _prepare_and_execute_task_with_callbacks
    result = self._execute_task(context, task_copy)
  File "/home/airflow/.local/lib/python3.6/site-packages/airflow/models/taskinstance.py", line 1315, in _execute_task
    result = task_copy.execute(context=context)
  File "/home/airflow/.local/lib/python3.6/site-packages/airflow/operators/python.py", line 117, in execute
    return_value = self.execute_callable()
  File "/home/airflow/.local/lib/python3.6/site-packages/airflow/operators/python.py", line 128, in execute_callable
    return self.python_callable(*self.op_args, **self.op_kwargs)
  File "/opt/airflow/dags/classification.py", line 104, in apply_dl_model
    img = image.load_img(os.path.join(process_dir,filename), target_size=(64, 64))
  File "/usr/local/lib/python3.6/site-packages/keras/preprocessing/image.py", line 314, in load_img
    target_size=target_size, interpolation=interpolation)
  File "/usr/local/lib/python3.6/site-packages/keras_preprocessing/image/utils.py", line 113, in load_img
    with open(path, 'rb') as f:
FileNotFoundError: [Errno 2] No such file or directory: '/opt/airflow/dags/process_dir/bulbasaur_bulbasaur_pikachu_654.jpeg'
[2022-01-25 11:05:58,180] {taskinstance.py:1503} INFO - Marking task as FAILED. dag_id=classification, task_id=apply_model, execution_date=20220125T105224, start_date=20220125T110255, end_date=20220125T110558
[2022-01-25 11:05:58,364] {local_task_job.py:146} INFO - Task exited with return code 1
